Workbook

Sheet Sprint 1
A1: Project name: | C1: SmartTrial | F1: Kết thúc
A2: Module name: | C2: Sprint 1 | F2: Tăng ca
A3: Start date: | C3: 46244 | F3: Muộn
A4: End date: | C4: 46182 | F4: Chậm tiến độ
F5: Trước thời hạn
B6: SPRINT 1 REPORT
B7: No | C7: Thành viên | D7: Thực tế | E7: Ước tính
B8: 1 | C8: Phạm Phú Hưng | D8: =SUMIF($D$15:$D$65,"*Hưng*",E$15:E$65)+SUMIF($D$15:$D$65,"All team",E$15:E$65) -> 18 | E8: =SUMIF($D$15:$D$65,"*Hưng*",F$15:F$65)+SUMIF($D$15:$D$65,"All team",F$15:F$65) -> 18
B9: 2 | C9: Nguyễn Minh Khôi | D9: =SUMIF($D$15:$D$65,"*Khôi*",E$15:E$65)-SUMIF($D$15:$D$65,"*Đăng Khôi*",E$15:E$65)+SUMIF($D$15:$D$65,"All team",E$15:E$65) -> 18.5 | E9: =SUMIF($D$15:$D$65,"*Khôi*",F$15:F$65)-SUMIF($D$15:$D$65,"*Đăng Khôi*",F$15:F$65)+SUMIF($D$15:$D$65,"All team",F$15:F$65) -> 19
B10: 3 | C10: Nguyễn Đăng Khôi | D10: =SUMIF($D$15:$D$65,"*Đăng Khôi*",E$15:E$65)+SUMIF($D$15:$D$65,"All team",E$15:E$65) -> 21 | E10: =SUMIF($D$15:$D$65,"*Đăng Khôi*",F$15:F$65)+SUMIF($D$15:$D$65,"All team",F$15:F$65) -> 19
B11: 4 | C11: Trần Tấn Huy | D11: =SUMIF($D$15:$D$65,"*Huy*",E$15:E$65)+SUMIF($D$15:$D$65,"All team",E$15:E$65) -> 19 | E11: =SUMIF($D$15:$D$65,"*Huy*",F$15:F$65)+SUMIF($D$15:$D$65,"All team",F$15:F$65) -> 19
B12: Tổng | D12: =SUM(D8:D11) -> 76.5 | E12: =SUM(E8:E11) -> 75
A14: Sprint | B14: Component | C14: Task name | D14: Responsible Member | E14: Thực tế | F14: Ước tính | G14: 26/8 | H14: 27/08 | I14: 28/08 | J14: 29/08 | K14: 30/08 | L14: 31/08 | M14: 46031 | N14: 46062 | O14: 46090 | P14: 46121 | Q14: 46151 | R14: 46182 | S14: 46212 | T14: 46243 | U14: 46274 | V14: 46304 | W14: 46335 | AK14: Ngày | AL14: 26/8 | AM14: 27/08 | AN14: 28/08 | AO14: 29/08 | AP14: 30/08 | AQ14: 31/08 | AR14: 46031 | AS14: 46062 | AT14: 46090 | AU14: 46121 | AV14: 46151 | AW14: 46182 | AX14: 46212 | AY14: 46243 | AZ14: 46274 | BA14: 46304 | BB14: 46335
A15: SPRINT 1 | B15: Sprint Planning | C15: Họp kế hoạch Sprint 1 | D15: All team | E15: 1 | F15: 1 | G15: 0 | H15: 0 | I15: 0 | J15: 0 | K15: 0 | L15: 0 | M15: 0 | N15: 0 | O15: 0 | P15: 0 | Q15: 0 | R15: 0 | S15: 0 | T15: 0 | U15: 0 | V15: 0 | W15: 0 | AK15: Thực tế | AL15: =G66 -> 55 | AM15: =H66 -> 53.5 | AN15: =I66 -> 51 | AO15: =J66 -> 45 | AP15: =K66 -> 40 | AQ15: =L66 -> 37 | AR15: =M66 -> 36 | AS15: =N66 -> 31 | ... BB15: =W66 -> 0
C16: Tạo Sprint Backlog 1 | D16: Khôi, Đăng Khôi | E16: 1 | F16: 1 | G16: 1 | H16: 0 | I16: 0 | J16: 0 | K16: 0 | L16: 0 | M16: 0 | N16: 0 | O16: 0 | P16: 0 | Q16: 0 | R16: 0 | S16: 0 | T16: 0 | U16: 0 | V16: 0 | W16: 0 | AK16: Ước tính | AL16: =G67 -> 55 | AM16: =H67 -> 53 | AN16: =I67 -> 51.5 | AO16: =J67 -> 45 | AP16: =K67 -> 40 | AQ16: =L67 -> 37 | AR16: =M67 -> 36 | AS16: =N67 -> 31 | ... BB16: =W67 -> 0
C17: Tạo tài liệu kiểm thử cho Sprint 1 | D17: Huy, Khôi | E17: 1 | F17: 1 | G17: 1 | H17: 0 | I17: 0 | J17: 0 | K17: 0 | L17: 0 | M17: 0 | N17: 0 | O17: 0 | P17: 0 | Q17: 0 | R17: 0 | S17: 0 | T17: 0 | U17: 0 | V17: 0 | W17: 0
B18: User interface design | C18: Thiết kế giao diện Đăng nhập | D18: Huy | E18: 1 | F18: 1 | G18: 1 | H18: 1 | I18: 0 | J18: 0 | K18: 0 | L18: 0 | M18: 0 | N18: 0 | O18: 0 | P18: 0 | Q18: 0 | R18: 0 | S18: 0 | T18: 0 | U18: 0 | V18: 0 | W18: 0
C19: Thiết kế giao diện Đăng ký | D19: Khôi | E19: 0.5 | F19: 1 | G19: 1 | H19: 1 | I19: 0 | J19: 0 | K19: 0 | L19: 0 | M19: 0 | N19: 0 | O19: 0 | P19: 0 | Q19: 0 | R19: 0 | S19: 0 | T19: 0 | U19: 0 | V19: 0 | W19: 0
I20: 0.5
C21: Thiết kế giao diện Đổi mật khẩu | D21: Huy | E21: 1 | F21: 1 | G21: 1 | H21: 1 | I21: 1 | J21: 0 | K21: 0 | L21: 0 | M21: 0 | N21: 0 | O21: 0 | P21: 0 | Q21: 0 | R21: 0 | S21: 0 | T21: 0 | U21: 0 | V21: 0 | W21: 0
C22: Thiết kế giao diện Tài khoản cá nhân | D22: Khôi | E22: 1 | F22: 1 | G22: 1 | H22: 1 | I22: 1 | J22: 0 | K22: 0 | L22: 0 | M22: 0 | N22: 0 | O22: 0 | P22: 0 | Q22: 0 | R22: 0 | S22: 0 | T22: 0 | U22: 0 | V22: 0 | W22: 0
C23: Thiết kế giao diện Lấy lại mật khẩu | D23: Huy | E23: 1 | F23: 1 | G23: 1 | H23: 1 | I23: 1 | J23: 0 | K23: 0 | L23: 0 | M23: 0 | N23: 0 | O23: 0 | P23: 0 | Q23: 0 | R23: 0 | S23: 0 | T23: 0 | U23: 0 | V23: 0 | W23: 0
C24: Thiết kế giao diện Xem thông tin giáo viên | D24: Khôi | E24: 1 | F24: 1 | G24: 1 | H24: 1 | I24: 1 | J24: 0 | K24: 0 | L24: 0 | M24: 0 | N24: 0 | O24: 0 | P24: 0 | Q24: 0 | R24: 0 | S24: 0 | T24: 0 | U24: 0 | V24: 0 | W24: 0
C25: Thiết kế giao diện Tìm kiếm giáo viên | D25: Huy | E25: 1 | F25: 1 | G25: 1 | H25: 1 | I25: 1 | J25: 0 | K25: 0 | L25: 0 | M25: 0 | N25: 0 | O25: 0 | P25: 0 | Q25: 0 | R25: 0 | S25: 0 | T25: 0 | U25: 0 | V25: 0 | W25: 0
C26: Thiết kế giao diện Xem lịch trống | D26: Khôi | E26: 1 | F26: 1 | G26: 1 | H26: 1 | I26: 1 | J26: 0 | K26: 0 | L26: 0 | M26: 0 | N26: 0 | O26: 0 | P26: 0 | Q26: 0 | R26: 0 | S26: 0 | T26: 0 | U26: 0 | V26: 0 | W26: 0
C27: Review toàn bộ giao diện Sprint | D27: All team | E27: 1 | F27: 1 | G27: 1 | H27: 1 | I27: 1 | J27: 1 | K27: 0 | L27: 0 | M27: 0 | N27: 0 | O27: 0 | P27: 0 | Q27: 0 | R27: 0 | S27: 0 | T27: 0 | U27: 0 | V27: 0 | W27: 0
B28: Design test case | C28: Thiết kế test case cho Đăng nhập | D28: Huy | E28: 1 | F28: 1 | G28: 1 | H28: 1 | I28: 1 | J28: 1 | K28: 0 | L28: 0 | M28: 0 | N28: 0 | O28: 0 | P28: 0 | Q28: 0 | R28: 0 | S28: 0 | T28: 0 | U28: 0 | V28: 0 | W28: 0
C29: Thiết kế test case cho Đăng ký | D29: Khôi | E29: 1 | F29: 1 | G29: 1 | H29: 1 | I29: 1 | J29: 1 | K29: 0 | L29: 0 | M29: 0 | N29: 0 | O29: 0 | P29: 0 | Q29: 0 | R29: 0 | S29: 0 | T29: 0 | U29: 0 | V29: 0 | W29: 0
C30: Thiết kế test case cho Đổi mật khẩu | D30: Huy | E30: 1 | F30: 1 | G30: 1 | H30: 1 | I30: 1 | J30: 1 | K30: 0 | L30: 0 | M30: 0 | N30: 0 | O30: 0 | P30: 0 | Q30: 0 | R30: 0 | S30: 0 | T30: 0 | U30: 0 | V30: 0 | W30: 0
C31: Thiết kế test case cho Tài khoản cá nhân | D31: Khôi | E31: 1 | F31: 1 | G31: 1 | H31: 1 | I31: 1 | J31: 1 | K31: 0 | L31: 0 | M31: 0 | N31: 0 | O31: 0 | P31: 0 | Q31: 0 | R31: 0 | S31: 0 | T31: 0 | U31: 0 | V31: 0 | W31: 0
C32: Thiết kế test case cho Lấy lại mật khẩu | D32: Huy | E32: 1 | F32: 1 | G32: 1 | H32: 1 | I32: 1 | J32: 1 | K32: 1 | L32: 0 | M32: 0 | N32: 0 | O32: 0 | P32: 0 | Q32: 0 | R32: 0 | S32: 0 | T32: 0 | U32: 0 | V32: 0 | W32: 0
C33: Thiết kế test case cho Xem thông tin giáo viên | D33: Khôi | E33: 1 | F33: 1 | G33: 1 | H33: 1 | I33: 1 | J33: 1 | K33: 1 | L33: 0 | M33: 0 | N33: 0 | O33: 0 | P33: 0 | Q33: 0 | R33: 0 | S33: 0 | T33: 0 | U33: 0 | V33: 0 | W33: 0
C34: Thiết kế test case cho Tìm kiếm giáo viên | D34: Huy | E34: 1 | F34: 1 | G34: 1 | H34: 1 | I34: 1 | J34: 1 | K34: 1 | L34: 1 | M34: 0 | N34: 0 | O34: 0 | P34: 0 | Q34: 0 | R34: 0 | S34: 0 | T34: 0 | U34: 0 | V34: 0 | W34: 0
C35: Thiết kế test case cho Xem lịch trống | D35: Khôi | E35: 1 | F35: 1 | G35: 1 | H35: 1 | I35: 1 | J35: 1 | K35: 1 | L35: 0 | M35: 0 | N35: 0 | O35: 0 | P35: 0 | Q35: 0 | R35: 0 | S35: 0 | T35: 0 | U35: 0 | V35: 0 | W35: 0
C36: Review toàn bộ test case Sprint | D36: All team | E36: 1 | F36: 1 | G36: 1 | H36: 1 | I36: 1 | J36: 1 | K36: 1 | L36: 1 | M36: 1 | N36: 0 | O36: 0 | P36: 0 | Q36: 0 | R36: 0 | S36: 0 | T36: 0 | U36: 0 | V36: 0 | W36: 0
B37: Development | C37: Code chức năng Đăng nhập | D37: Đăng Khôi | E37: 2 | F37: 2 | G37: 2 | H37: 2 | I37: 2 | J37: 2 | K37: 2 | L37: 2 | M37: 2 | N37: 0 | O37: 0 | P37: 0 | Q37: 0 | R37: 0 | S37: 0 | T37: 0 | U37: 0 | V37: 0 | W37: 0
C38: Code chức năng Đăng ký | D38: Hưng | E38: 2 | F38: 2 | G38: 2 | H38: 2 | I38: 2 | J38: 2 | K38: 2 | L38: 2 | M38: 2 | N38: 0 | O38: 0 | P38: 0 | Q38: 0 | R38: 0 | S38: 0 | T38: 0 | U38: 0 | V38: 0 | W38: 0
C39: Code chức năng Đổi mật khẩu | D39: Đăng Khôi | E39: 3 | F39: 2 | G39: 2 | H39: 2 | I39: 2 | J39: 2 | K39: 2 | L39: 2 | M39: 2 | N39: 2 | O39: 2 | P39: 0 | Q39: 0 | R39: 0 | S39: 0 | T39: 0 | U39: 0 | V39: 0 | W39: 0
P40: 1
C41: Code chức năng Tài khoản cá nhân | D41: Hưng | E41: 2 | F41: 2 | G41: 2 | H41: 2 | I41: 2 | J41: 2 | K41: 2 | L41: 2 | M41: 2 | N41: 2 | O41: 2 | P41: 0 | Q41: 0 | R41: 0 | S41: 0 | T41: 0 | U41: 0 | V41: 0 | W41: 0
...

Sheet Sprint 2
A1: Project name: | C1: SmartTrial | F1: Kết thúc
A2: Module name: | C2: Sprint 2 | F2: Tăng ca
A3: Start date: | C3: 46212 | F3: Muộn
A4: End date: | C4: 46122 | F4: Chậm tiến độ
F5: Trước thời hạn
B6: SPRINT 2 REPORT
B7: No | C7: Thành viên | D7: Thực tế | E7: Ước tính
B8: 1 | C8: Phạm Phú Hưng | D8: =SUMIF($D$15:$D$65,"*Hưng*",E$15:E$65)+SUMIF($D$15:$D$65,"All team",E$15:E$65) -> 18 | E8: =SUMIF($D$15:$D$65,"*Hưng*",F$15:F$65)+SUMIF($D$15:$D$65,"All team",F$15:F$65) -> 18
B9: 2 | C9: Nguyễn Minh Khôi | D9: =SUMIF($D$15:$D$65,"*Khôi*",E$15:E$65)-SUMIF($D$15:$D$65,"*Đăng Khôi*",E$15:E$65)+SUMIF($D$15:$D$65,"All team",E$15:E$65) -> 19.5 | E9: =SUMIF($D$15:$D$65,"*Khôi*",F$15:F$65)-SUMIF($D$15:$D$65,"*Đăng Khôi*",F$15:F$65)+SUMIF($D$15:$D$65,"All team",F$15:F$65) -> 19
B10: 3 | C10: Trần Tấn Huy | D10: =SUMIF($D$15:$D$65,"*Huy*",E$15:E$65)+SUMIF($D$15:$D$65,"All team",E$15:E$65) -> 19 | E10: =SUMIF($D$15:$D$65,"*Khôi*",F$15:F$65)-SUMIF($D$15:$D$65,"*Đăng Khôi*",F$15:F$65)+SUMIF($D$15:$D$65,"All team",F$15:F$65) -> 19
B11: 4 | C11: Nguyễn Đăng Khôi | D11: =SUMIF($D$15:$D$65,"*Đăng Khôi*",E$15:E$65)+SUMIF($D$15:$D$65,"All team",E$15:E$65) -> 20 | E11: =SUMIF($D$15:$D$65,"*Đăng Khôi*",F$15:F$65)+SUMIF($D$15:$D$65,"All team",F$15:F$65) -> 19
B12: Tổng | D12: =SUM(D8:D11) -> 76.5 | E12: =SUM(E8:E11) -> 75
A14: Sprint | B14: Component | C14: Task name | D14: Responsible Member | E14: Thực tế | F14: Ước tính | G14: 46365 | H14: 13/09 | I14: 14/09 | J14: 15/09 | K14: 16/09 | L14: 17/09 | M14: 18/09 | N14: 19/09 | O14: 20/09 | P14: 21/09 | Q14: 22/09 | R14: 23/09 | S14: 24/09 | T14: 25/09 | U14: 26/09 | V14: 27/09 | W14: 28/9/2026 | X14: 29/09/2026 | Y14: 30/9/2026 | Z14: 46032 | AA14: 46063 | AB14: 46091 | AC14: 46122 | AD14: 46152 | AE14: 46183 | AL14: Ngày | AM14: 46365 | AN14: 13/09 | AO14: 14/09 | AP14: 15/09 | AQ14: 16/09 | AR14: 17/09 | AS14: 18/09 | AT14: 19/09 | AU14: 20/09 | AV14: 21/09 | AW14: 22/09 | AX14: 23/09 | AY14: 24/09 | AZ14: 25/09 | BA14: 26/09 | BB14: 27/09 | BC14: 28/9/2026 | BD14: 29/09/2026 | BE14: 30/9/2026 | BF14: 46032 | BG14: 46063 | BH14: 46091 | BI14: 46122 | BJ14: 46152 | BK14: 46183
A15: SPRINT 2 | B15: Sprint Planning | C15: Họp kế hoạch Sprint 2 | D15: All team | E15: 1 | F15: 1 | G15: 0 | H15: 0 | I15: 0 | J15: 0 | K15: 0 | L15: 0 | M15: 0 | N15: 0 | O15: 0 | P15: 0 | Q15: 0 | R15: 0 | S15: 0 | T15: 0 | U15: 0 | V15: 0 | W15: 0 | X15: 0 | Y15: 0 | Z15: 0 | AA15: 0 | AB15: 0 | AC15: 0 | AD15: 0 | AE15: 0 | AL15: Thực tế | AM15: =G66 -> 55 | AN15: =H66 -> 54 | AO15: =I66 -> 53 | AP15: =J66 -> 51 | AQ15: =K66 -> 49 | AR15: =L66 -> 46.5 | AS15: =M66 -> 45 | AT15: =N66 -> 44 | ... BK15: =AE66 -> 0
C16: Tạo Sprint Backlog 2 | D16: Khôi, Đăng Khôi | E16: 1 | F16: 1 | G16: 1 | H16: 0 | I16: 0 | J16: 0 | K16: 0 | L16: 0 | M16: 0 | N16: 0 | O16: 0 | P16: 0 | Q16: 0 | R16: 0 | S16: 0 | T16: 0 | U16: 0 | V16: 0 | W16: 0 | X16: 0 | Y16: 0 | Z16: 0 | AA16: 0 | AB16: 0 | AC16: 0 | AD16: 0 | AE16: 0 | AL16: Ước tính | AM16: =G67 -> 56 | AN16: =H67 -> 55 | AO16: =I67 -> 54 | AP16: =J67 -> 53 | AQ16: =K67 -> 51 | AR16: =L67 -> 49 | AS16: =M67 -> 47.5 | AT16: =N67 -> 45 | ... BK16: =AE67 -> 0 | BY16: =CW67 -> 0 | BZ16: =CX67 -> 0 | CA16: =CY67 -> 0 | CB16: =CZ67 -> 0 | CC16: =DA67 -> 0 | CD16: =DB67 -> 0 | CE16: =DC67 -> 0 | CF16: =DD67 -> 0 | ... CU16: =DS67 -> 0
C17: Tạo tài liệu kiểm thử cho Sprint 2 | D17: Huy, Khôi | E17: 1 | F17: 1 | G17: 1 | H17: 1 | I17: 0 | J17: 0 | K17: 0 | L17: 0 | M17: 0 | N17: 0 | O17: 0 | P17: 0 | Q17: 0 | R17: 0 | S17: 0 | T17: 0 | U17: 0 | V17: 0 | W17: 0 | X17: 0 | Y17: 0 | Z17: 0 | AA17: 0 | AB17: 0 | AC17: 0 | AD17: 0 | AE17: 0
B18: User interface design | C18: Thiết kế giao diện Quản lý lịch dạy | D18: Huy | E18: 1 | F18: 1 | G18: 1 | H18: 1 | I18: 1 | J18: 0 | K18: 0 | L18: 0 | M18: 0 | N18: 0 | O18: 0 | P18: 0 | Q18: 0 | R18: 0 | S18: 0 | T18: 0 | U18: 0 | V18: 0 | W18: 0 | X18: 0 | Y18: 0 | Z18: 0 | AA18: 0 | AB18: 0 | AC18: 0 | AD18: 0 | AE18: 0
C19: Thiết kế giao diện Đặt lịch học thử | D19: Khôi | E19: 1 | F19: 1 | G19: 1 | H19: 1 | I19: 1 | J19: 0 | K19: 0 | L19: 0 | M19: 0 | N19: 0 | O19: 0 | P19: 0 | Q19: 0 | R19: 0 | S19: 0 | T19: 0 | U19: 0 | V19: 0 | W19: 0 | X19: 0 | Y19: 0 | Z19: 0 | AA19: 0 | AB19: 0 | AC19: 0 | AD19: 0 | AE19: 0
C20: Thiết kế giao diện Xem lịch học | D20: Huy | E20: 1 | F20: 1 | G20: 1 | H20: 1 | I20: 1 | J20: 1 | K20: 0 | L20: 0 | M20: 0 | N20: 0 | O20: 0 | P20: 0 | Q20: 0 | R20: 0 | S20: 0 | T20: 0 | U20: 0 | V20: 0 | W20: 0 | X20: 0 | Y20: 0 | Z20: 0 | AA20: 0 | AB20: 0 | AC20: 0 | AD20: 0 | AE20: 0
C21: Thiết kế giao diện Quản lý yêu cầu đặt lịch | D21: Khôi | E21: 1 | F21: 1 | G21: 1 | H21: 1 | I21: 1 | J21: 1 | K21: 0 | L21: 0 | M21: 0 | N21: 0 | O21: 0 | P21: 0 | Q21: 0 | R21: 0 | S21: 0 | T21: 0 | U21: 0 | V21: 0 | W21: 0 | X21: 0 | Y21: 0 | Z21: 0 | AA21: 0 | AB21: 0 | AC21: 0 | AD21: 0 | AE21: 0
C22: Thiết kế giao diện Tư vấn trực tuyến | D22: Huy | E22: 1 | F22: 1 | G22: 1 | H22: 1 | I22: 1 | J22: 1 | K22: 1 | L22: 0 | M22: 0 | N22: 0 | O22: 0 | P22: 0 | Q22: 0 | R22: 0 | S22: 0 | T22: 0 | U22: 0 | V22: 0 | W22: 0 | X22: 0 | Y22: 0 | Z22: 0 | AA22: 0 | AB22: 0 | AC22: 0 | AD22: 0 | AE22: 0
C23: Thiết kế giao diện Chatbot AI | D23: Khôi | E23: 0.5 | F23: 1 | G23: 1 | H23: 1 | I23: 1 | J23: 1 | K23: 1 | L23: 0 | M23: 0 | N23: 0 | O23: 0 | P23: 0 | Q23: 0 | R23: 0 | S23: 0 | T23: 0 | U23: 0 | V23: 0 | W23: 0 | X23: 0 | Y23: 0 | Z23: 0 | AA23: 0 | AB23: 0 | AC23: 0 | AD23: 0 | AE23: 0
L24: 0.5
C25: Thiết kế giao diện Thanh toán | D25: Huy | E25: 1 | F25: 1 | G25: 1 | H25: 1 | I25: 1 | J25: 1 | K25: 1 | L25: 1 | M25: 0 | N25: 0 | O25: 0 | P25: 0 | Q25: 0 | R25: 0 | S25: 0 | T25: 0 | U25: 0 | V25: 0 | W25: 0 | X25: 0 | Y25: 0 | Z25: 0 | AA25: 0 | AB25: 0 | AC25: 0 | AD25: 0 | AE25: 0
C26: Thiết kế giao diện Báo cáo và thống kê | D26: Khôi | E26: 1 | F26: 1 | G26: 1 | H26: 1 | I26: 1 | J26: 1 | K26: 1 | L26: 1 | M26: 0 | N26: 0 | O26: 0 | P26: 0 | Q26: 0 | R26: 0 | S26: 0 | T26: 0 | U26: 0 | V26: 0 | W26: 0 | X26: 0 | Y26: 0 | Z26: 0 | AA26: 0 | AB26: 0 | AC26: 0 | AD26: 0 | AE26: 0
C27: Review toàn bộ giao diện Sprint | D27: All team | E27: 1 | F27: 1 | G27: 1 | H27: 1 | I27: 1 | J27: 1 | K27: 1 | L27: 1 | M27: 1 | N27: 0 | O27: 0 | P27: 0 | Q27: 0 | R27: 0 | S27: 0 | T27: 0 | U27: 0 | V27: 0 | W27: 0 | X27: 0 | Y27: 0 | Z27: 0 | AA27: 0 | AB27: 0 | AC27: 0 | AD27: 0 | AE27: 0
B28: Design test case | C28: Thiết kế test case cho Quản lý lịch dạy | D28: Huy | E28: 1 | F28: 1 | G28: 1 | H28: 1 | I28: 1 | J28: 1 | K28: 1 | L28: 1 | M28: 1 | N28: 1 | O28: 0 | P28: 0 | Q28: 0 | R28: 0 | S28: 0 | T28: 0 | U28: 0 | V28: 0 | W28: 0 | X28: 0 | Y28: 0 | Z28: 0 | AA28: 0 | AB28: 0 | AC28: 0 | AD28: 0 | AE28: 0
C29: Thiết kế test case cho Đặt lịch học thử | D29: Khôi | E29: 1 | F29: 1 | G29: 1 | H29: 1 | I29: 1 | J29: 1 | K29: 1 | L29: 1 | M29: 1 | N29: 1 | O29: 0 | P29: 0 | Q29: 0 | R29: 0 | S29: 0 | T29: 0 | U29: 0 | V29: 0 | W29: 0 | X29: 0 | Y29: 0 | Z29: 0 | AA29: 0 | AB29: 0 | AC29: 0 | AD29: 0 | AE29: 0
C30: Thiết kế test case cho Xem lịch học | D30: Huy | E30: 1 | F30: 1 | G30: 1 | H30: 1 | I30: 1 | J30: 1 | K30: 1 | L30: 1 | M30: 1 | N30: 1 | O30: 1 | P30: 0 | Q30: 0 | R30: 0 | S30: 0 | T30: 0 | U30: 0 | V30: 0 | W30: 0 | X30: 0 | Y30: 0 | Z30: 0 | AA30: 0 | AB30: 0 | AC30: 0 | AD30: 0 | AE30: 0
C31: Thiết kế test case cho Quản lý yêu cầu đặt lịch | D31: Khôi | E31: 1 | F31: 1 | G31: 1 | H31: 1 | I31: 1 | J31: 1 | K31: 1 | L31: 1 | M31: 1 | N31: 1 | O31: 1 | P31: 0 | Q31: 0 | R31: 0 | S31: 0 | T31: 0 | U31: 0 | V31: 0 | W31: 0 | X31: 0 | Y31: 0 | Z31: 0 | AA31: 0 | AB31: 0 | AC31: 0 | AD31: 0 | AE31: 0
C32: Thiết kế test case cho Tư vấn trực tuyến | D32: Huy | E32: 1 | F32: 1 | G32: 1 | H32: 1 | I32: 1 | J32: 1 | K32: 1 | L32: 1 | M32: 1 | N32: 1 | O32: 1 | P32: 1 | Q32: 0 | R32: 0 | S32: 0 | T32: 0 | U32: 0 | V32: 0 | W32: 0 | X32: 0 | Y32: 0 | Z32: 0 | AA32: 0 | AB32: 0 | AC32: 0 | AD32: 0 | AE32: 0
C33: Thiết kế test case cho Chatbot AI | D33: Khôi | E33: 1 | F33: 1 | G33: 1 | H33: 1 | I33: 1 | J33: 1 | K33: 1 | L33: 1 | M33: 1 | N33: 1 | O33: 1 | P33: 1 | Q33: 0 | R33: 0 | S33: 0 | T33: 0 | U33: 0 | V33: 0 | W33: 0 | X33: 0 | Y33: 0 | Z33: 0 | AA33: 0 | AB33: 0 | AC33: 0 | AD33: 0 | AE33: 0
C34: Thiết kế test case cho Thanh toán | D34: Huy | E34: 1 | F34: 1 | G34: 1 | H34: 1 | I34: 1 | J34: 1 | K34: 1 | L34: 1 | M34: 1 | N34: 1 | O34: 1 | P34: 1 | Q34: 1 | R34: 0 | S34: 0 | T34: 0 | U34: 0 | V34: 0 | W34: 0 | X34: 0 | Y34: 0 | Z34: 0 | AA34: 0 | AB34: 0 | AC34: 0 | AD34: 0 | AE34: 0
C35: Thiết kế test case cho Báo cáo và thống kê | D35: Khôi | E35: 1 | F35: 1 | G35: 1 | H35: 1 | I35: 1 | J35: 1 | K35: 1 | L35: 1 | M35: 1 | N35: 1 | O35: 1 | P35: 1 | Q35: 1 | R35: 0 | S35: 0 | T35: 0 | U35: 0 | V35: 0 | W35: 0 | X35: 0 | Y35: 0 | Z35: 0 | AA35: 0 | AB35: 0 | AC35: 0 | AD35: 0 | AE35: 0
C36: Review toàn bộ test case Sprint | D36: All team | E36: 1 | F36: 1 | G36: 1 | H36: 1 | I36: 1 | J36: 1 | K36: 1 | L36: 1 | M36: 1 | N36: 1 | O36: 1 | P36: 1 | Q36: 1 | R36: 1 | S36: 0 | T36: 0 | U36: 0 | V36: 0 | W36: 0 | X36: 0 | Y36: 0 | Z36: 0 | AA36: 0 | AB36: 0 | AC36: 0 | AD36: 0 | AE36: 0
B37: Development | C37: Code chức năng Quản lý lịch dạy | D37: Đăng Khôi | E37: 2 | F37: 2 | G37: 2 | H37: 2 | I37: 2 | J37: 2 | K37: 2 | L37: 2 | M37: 2 | N37: 2 | O37: 2 | P37: 2 | Q37: 2 | R37: 2 | S37: 0 | T37: 0 | U37: 0 | V37: 0 | W37: 0 | X37: 0 | Y37: 0 | Z37: 0 | AA37: 0 | AB37: 0 | AC37: 0 | AD37: 0 | AE37: 0
C38: Code chức năng Đặt lịch học thử | D38: Hưng | E38: 2 | F38: 2 | G38: 2 | H38: 2 | I38: 2 | J38: 2 | K38: 2 | L38: 2 | M38: 2 | N38: 2 | O38: 2 | P38: 2 | Q38: 2 | R38: 2 | S38: 0 | T38: 0 | U38: 0 | V38: 0 | W38: 0 | X38: 0 | Y38: 0 | Z38: 0 | AA38: 0 | AB38: 0 | AC38: 0 | AD38: 0 | AE38: 0
C39: Code chức năng Xem lịch học | D39: Đăng Khôi | E39: 2 | F39: 2 | G39: 2 | H39: 2 | I39: 2 | J39: 2 | K39: 2 | L39: 2 | M39: 2 | N39: 2 | O39: 2 | P39: 2 | Q39: 2 | R39: 2 | S39: 2 | T39: 2 | U39: 0 | V39: 0 | W39: 0 | X39: 0 | Y39: 0 | Z39: 0 | AA39: 0 | AB39: 0 | AC39: 0 | AD39: 0 | AE39: 0
C40: Code chức năng Quản lý yêu cầu đặt lịch | D40: Hưng | E40: 2 | F40: 2 | G40: 2 | H40: 2 | I40: 2 | J40: 2 | K40: 2 | L40: 2 | M40: 2 | N40: 2 | O40: 2 | P40: 2 | Q40: 2 | R40: 2 | S40: 2 | T40: 2 | U40: 0 | V40: 0 | W40: 0 | X40: 0 | Y40: 0 | Z40: 0 | AA40: 0 | AB40: 0 | AC40: 0 | AD40: 0 | AE40: 0
C41: Code chức năng Tư vấn trực tuyến | D41: Đăng Khôi | E41: 2 | F41: 2 | G41: 2 | H41: 2 | I41: 2 | J41: 2 | K41: 2 | L41: 2 | M41: 2 | N41: 2 | O41: 2 | P41: 2 | Q41: 2 | R41: 2 | S41: 2 | T41: 2 | U41: 2 | V41: 2 | W41: 0 | X41: 0 | Y41: 0 | Z41: 0 | AA41: 0 | AB41: 0 | AC41: 0 | AD41: 0 | AE41: 0
...

Sheet Total
A1: SPRINT BACKLOG REPORT
B2: Hưng | D2: Minh Khôi | F2: Đăng Khôi | H2: Huy
B3: Thực tế | C3: Ước tính | D3: Thực tế | E3: Ước tính | F3: Thực tế | G3: Ước tính | H3: Thực tế | I3: Ước tính
A4: Sprint 1 | B4: ='Sprint 1'!$D$8 -> 18 | C4: ='Sprint 1'!$E$8 -> 18 | D4: ='Sprint 1'!$D$9 -> 18.5 | E4: ='Sprint 1'!$E$9 -> 19 | F4: ='Sprint 1'!$D$10 -> 21 | G4: ='Sprint 1'!$E$10 -> 19 | H4: ='Sprint 1'!$D$11 -> 19 | I4: ='Sprint 1'!$E$11 -> 19
A5: Sprint 2 | B5: ='Sprint 2'!$D$8 -> 18 | C5: ='Sprint 2'!$E$8 -> 18 | D5: ='Sprint 2'!$D$9 -> 19.5 | E5: ='Sprint 2'!$E$9 -> 19 | F5: ='Sprint 2'!$D$11 -> 20 | G5: ='Sprint 2'!$E$11 -> 19 | H5: ='Sprint 2'!$D$10 -> 19 | I5: ='Sprint 2'!$E$10 -> 19
A6: Tổng | B6: =SUM(B4:B5) -> 36 | C6: =SUM(C4:C5) -> 36 | D6: =SUM(D4:D5) -> 38 | E6: =SUM(E4:E5) -> 38 | F6: =SUM(F4:F5) -> 41 | G6: =SUM(G4:G5) -> 38 | H6: =SUM(H4:H5) -> 38 | I6: =SUM(I4:I5) -> 38
E9: FINAL TOTAL
E10: Thực tế | F10: =SUMIF($B$3:$I$3,"Thực tế",$B$6:$I$6) -> 153
E11: Ước tính | F11: =SUMIF($B$3:$I$3,"Ước tính",$B$6:$I$6) -> 150
